<mujoco model="fr3_husky">
    <compiler angle="radian" meshdir="assets"/>

  <option timestep="0.001" integrator="implicitfast"/>

    <default>
        <default class="fr3_husky">
            <material specular="0.5" shininess="0.25"/>
            <joint armature="0.1" damping="1"/>
            <position inheritrange="1"/>
            <default class="visual">
                <geom type="mesh" group="2" contype="0" conaffinity="0"/>
            </default>
            <default class="collision">
                <geom type="mesh" group="3" mass="0" density="0"/>
            </default>
            <site size="0.001" rgba="0.5 0.5 0.5 0.3" group="4"/>
        </default>
    </default>
    
    <asset>
        <!-- Husky -->
        <material class="fr3_husky" name="husky_orange" rgba="0.996 0.941 0.412 1.0"/>
        <material class="fr3_husky" name="husky_black" rgba="0.231 0.231 0.231 1.0"/>

        <mesh name="base_link"     file="husky/base_link.stl"/>
        <mesh name="wheel"         file="husky/wheel.stl"/>
        <mesh name="bumper"        file="husky/bumper.stl"/>
        <mesh name="top_chassis"   file="husky/top_chassis.stl"/>
        <mesh name="top_structure" file="husky/roas_dyros.STL"/>
        <mesh name="top_plate"     file="husky/top_plate.stl"/>
        <mesh name="user_rail"     file="husky/user_rail.stl"/>

        <!-- FR3 -->
        <material name="black" rgba=".2 .2 .2 1"/>
        <material name="white" rgba="1 1 1 1"/>
        <material name="red" rgba="1 0.072272 0.039546 1"/>
        <material name="gray" rgba="0.863156 0.863156 0.863157 1"/>
        <material name="button_green" rgba="0.102241 0.571125 0.102242 1"/>
        <material name="button_red" rgba="0.520996 0.008023 0.013702 1"/>
        <material name="button_blue" rgba="0.024157 0.445201 0.737911 1"/>

        <mesh file="fr3/link0_0.obj"/>
        <mesh file="fr3/link0_1.obj"/>
        <mesh file="fr3/link0_2.obj"/>
        <mesh file="fr3/link0_3.obj"/>
        <mesh file="fr3/link0_4.obj"/>
        <mesh file="fr3/link0_5.obj"/>
        <mesh file="fr3/link0_6.obj"/>
        <mesh file="fr3/link1.obj"/>
        <mesh file="fr3/link2.obj"/>
        <mesh file="fr3/link3_0.obj"/>
        <mesh file="fr3/link3_1.obj"/>
        <mesh file="fr3/link4_0.obj"/>
        <mesh file="fr3/link4_1.obj"/>
        <mesh file="fr3/link5_0.obj"/>
        <mesh file="fr3/link5_1.obj"/>
        <mesh file="fr3/link5_2.obj"/>
        <mesh file="fr3/link6_0.obj"/>
        <mesh file="fr3/link6_1.obj"/>
        <mesh file="fr3/link6_2.obj"/>
        <mesh file="fr3/link6_3.obj"/>
        <mesh file="fr3/link6_4.obj"/>
        <mesh file="fr3/link6_5.obj"/>
        <mesh file="fr3/link6_6.obj"/>
        <mesh file="fr3/link6_7.obj"/>
        <mesh file="fr3/link7_0.obj"/>
        <mesh file="fr3/link7_1.obj"/>
        <mesh file="fr3/link7_2.obj"/>
        <mesh file="fr3/link7_3.obj"/>

        <mesh name="link0_coll" file="fr3/link0.stl"/>
        <mesh name="link1_coll" file="fr3/link1.stl"/>
        <mesh name="link2_coll" file="fr3/link2.stl"/>
        <mesh name="link3_coll" file="fr3/link3.stl"/>
        <mesh name="link4_coll" file="fr3/link4.stl"/>
        <mesh name="link5_coll" file="fr3/link5.stl"/>
        <mesh name="link6_coll" file="fr3/link6.stl"/>
        <mesh name="link7_coll" file="fr3/link7.stl"/>
    </asset>

    <worldbody>
        <!-- Floating base -->
        <body name="x_slider" pos="0 0 0">
            <inertial pos="0 0 0" mass="1e-4" diaginertia="4e-9 4e-9 4e-9"/>
            <joint name="x_base_joint" type="slide" pos="0 0 0" axis="1 0 0"/>
            <body name="y_slider" pos="0 0 0">
                <inertial pos="0 0 0" mass="1e-4" diaginertia="4e-9 4e-9 4e-9"/>
                <joint name="y_base_joint" type="slide" pos="0 0 0" axis="0 1 0"/>
                <body name="z_slider" pos="0 0 1">
                <inertial pos="0 0 0" mass="1e-4" diaginertia="4e-9 4e-9 4e-9"/>
                <joint name="z_base_joint" type="slide" pos="0 0 0" axis="0 0 1"/>
                    <body name="pivot" pos="0 0 0">
                        <inertial pos="0 0 0" mass="1e-4" diaginertia="4e-9 4e-9 4e-9"/>
                        <joint name="pivot_joint" type="hinge" pos="0 0 0" axis="0 0 1"/>
                        <body name="base_footprint" pos="0 0 0.13228">
                            <!-- <joint type="free" stiffness="0" damping="0" frictionloss="0" armature="0" /> -->

                            <body name="base" pos="0 0 0">
                                <inertial pos="-0.00065 -0.085 0.062"  mass="46.034" fullinertia="0.6022 1.7386 2.0296 -0.02364 -0.1197 -0.001544"/>
                                <geom class="collision" size="0.4937 0.28545 0.061875" pos="0 0 0.061875" type="box"/>
                                <geom class="collision" size="0.39496 0.28545 0.051875" pos="0 0 0.175625" type="box"/>
                                <geom class="visual" pos="0.272 0 0.245" type="mesh" mesh="user_rail" material="husky_black"/>
                                <geom class="visual" pos="0.0812 0 0.245" type="mesh" mesh="top_plate" material="husky_black"/>
                                <geom class="visual" pos="-0.48 0 0.091" quat="0 0 1 0" type="mesh" mesh="bumper" rgba="0.2 0.2 0.2 1.0"/>
                                <geom class="visual" pos="0.48 0 0.091" type="mesh" mesh="bumper" rgba="0.2 0.2 0.2 1.0"/>
                                <geom class="visual" pos="0 0 0" type="mesh" mesh="base_link" rgba="0.8 0.8 0.0 1.0"/>
                                <geom class="visual" pos="0 0 0" type="mesh" mesh="top_chassis" rgba="0.8 0.8 0.0 1.0"/>
                                <site name="husky_site"  size = "0.005" rgba = ".1 .1 .9 1" type = "sphere" />

                                <body name="top_structure_link" pos="0 0 0">
                                    <inertial pos="-0.2 0 0.85" mass="40" 
                                        fullinertia="1.95397859e-01 1.92679403e-01 1.01958752e-01 7.23330468e-08 2.01114568e-02 -7.81325404e-05"/>
                                    <geom class="visual" pos="0 0 0" type="mesh" mesh="top_structure" material="husky_black"/>
                                    <geom class="collision" size="0.19496 0.28 0.6825" pos="-0.2 0 0.8" type="box"/>
                                </body>

                                <body name="front_left_wheel" pos="0.256 0.2854 0.03282">
                                    <inertial pos="0 0 0" quat="0.707107 0 0 0.707107" mass="2.637" diaginertia="0.04411 0.02467 0.02467"/>
                                    <joint name="front_left_wheel" type="hinge" pos="0 0 0" axis="0 1 0"/>
                                    <geom class="visual" pos="0 0 0" quat="0 0 0 1" mesh="wheel" material="husky_black"/>
                                    <geom class="collision" size="0.1651 0.05715" quat="0.707107 0.707106 0 0" type="cylinder"/>
                                </body>

                                <body name="front_right_wheel" pos="0.256 -0.2854 0.03282">
                                    <inertial pos="0 0 0" quat="0.707107 0 0 0.707107" mass="2.637" diaginertia="0.04411 0.02467 0.02467"/>
                                    <joint name="front_right_wheel" type="hinge" pos="0 0 0" axis="0 1 0"/>
                                    <geom class="visual" pos="0 0 0" quat="0 0 0 1" mesh="wheel" material="husky_black"/>
                                    <geom class="collision" size="0.1651 0.05715" quat="0.707107 0.707106 0 0" type="cylinder"/>
                                </body>

                                <body name="rear_left_wheel" pos="-0.256 0.2854 0.03282">
                                    <inertial pos="0 0 0" quat="0.707107 0 0 0.707107" mass="2.637" diaginertia="0.04411 0.02467 0.02467"/>
                                    <joint name="rear_left_wheel" type="hinge" pos="0 0 0" axis="0 1 0"/>
                                    <geom class="visual" pos="0 0 0" quat="0 0 0 1" mesh="wheel" material="husky_black"/>
                                    <geom class="collision" size="0.1651 0.05715" quat="0.707107 0.707106 0 0" type="cylinder"/>
                                </body>

                                <body name="rear_right_wheel" pos="-0.256 -0.2854 0.03282">
                                    <inertial pos="0 0 0" quat="0.707107 0 0 0.707107" mass="2.637" diaginertia="0.04411 0.02467 0.02467"/>
                                    <joint name="rear_right_wheel" type="hinge" pos="0 0 0" axis="0 1 0" />
                                    <geom class="visual" pos="0 0 0" quat="0 0 0 1" mesh="wheel" material="husky_black"/>
                                    <geom class="collision" size="0.1651 0.05715" quat="0.707107 0.707106 0 0" type="cylinder"/>
                                </body>
                        
                                <!-- FR3 -->
                                <body name="fr3_base" childclass="fr3_husky" pos="0.36 0 0.25">
                                    <body name="fr3_link0" >
                                        <geom mesh="link0_0" material="black" class="visual"/>
                                        <geom mesh="link0_1" material="white" class="visual"/>
                                        <geom mesh="link0_2" material="white" class="visual"/>
                                        <geom mesh="link0_3" material="white" class="visual"/>
                                        <geom mesh="link0_4" material="white" class="visual"/>
                                        <geom mesh="link0_5" material="red" class="visual"/>
                                        <geom mesh="link0_6" material="black" class="visual"/>
                                        <geom name="fr3_link0_collision" mesh="link0_coll" class="collision"/>
                                        
                                        <body name="fr3_link1" pos="0 0 0.333" >
                                            <inertial pos="4.128e-07 -0.0181251 -0.0386036" quat="0.998098 -0.0605364 0.00380499 0.0110109" mass="2.92747"
                                                diaginertia="0.0239286 0.0227246 0.00610634"/>
                                            <joint name="fr3_joint1" axis="0 0 1" range="-2.7437 2.7437" actuatorfrcrange="-87 87"/>
                                            <geom name="fr3_link1_collision" class="collision" mesh="link1_coll"/>
                                            <geom material="white" mesh="link1" class="visual"/>

                                            <body name="fr3_link2" quat="1 -1 0 0" >
                                                <inertial pos="0.00318289 -0.0743222 0.00881461" quat="0.502599 0.584437 -0.465998 0.434366" mass="2.93554"
                                                diaginertia="0.0629567 0.0411924 0.0246371"/>
                                                <joint name="fr3_joint2" axis="0 0 1" range="-1.7837 1.7837" actuatorfrcrange="-87 87"/>
                                                <geom material="white" mesh="link2" class="visual"/>
                                                <geom name="fr3_link2_collision" class="collision" mesh="link2_coll"/>

                                                <body name="fr3_link3" pos="0 -0.316 0" quat="1 1 0 0" >
                                                    <inertial pos="0.0407016 -0.00482006 -0.0289731" quat="0.921025 -0.244161 0.155272 0.260745" mass="2.2449"
                                                        diaginertia="0.0267409 0.0189869 0.0171587"/>
                                                    <joint name="fr3_joint3" axis="0 0 1" range="-2.9007 2.9007" actuatorfrcrange="-87 87"/>
                                                    <geom mesh="link3_0" material="white" class="visual"/>
                                                    <geom mesh="link3_1" material="black" class="visual"/>
                                                    <geom name="fr3_link3_collision" class="collision" mesh="link3_coll"/>

                                                    <body name="fr3_link4" pos="0.0825 0 0" quat="1 1 0 0" >
                                                        <inertial pos="-0.0459101 0.0630493 -0.00851879" quat="0.438018 0.803311 0.00937812 0.403414"
                                                        mass="2.6156" diaginertia="0.05139 0.0372717 0.0160047"/>
                                                        <joint name="fr3_joint4" axis="0 0 1" range="-3.0421 -0.1518" actuatorfrcrange="-87 87"/>
                                                        <geom mesh="link4_0" material="white" class="visual"/>
                                                        <geom mesh="link4_1" material="black" class="visual"/>
                                                        <geom name="fr3_link4_collision" class="collision" mesh="link4_coll"/>

                                                        <body name="fr3_link5" pos="-0.0825 0.384 0" quat="1 -1 0 0" >
                                                            <inertial pos="-0.00160396 0.0292536 -0.0972966" quat="0.919031 0.125604 0.0751531 -0.366003"
                                                                mass="2.32712" diaginertia="0.0579335 0.0449144 0.0130634"/>
                                                            <joint name="fr3_joint5" axis="0 0 1" range="-2.8065 2.8065" actuatorfrcrange="-12 12"/>
                                                            <geom mesh="link5_0" material="white" class="visual"/>
                                                            <geom mesh="link5_1" material="white" class="visual"/>
                                                            <geom mesh="link5_2" material="black" class="visual"/>
                                                            <geom name="fr3_link5_collision" class="collision" mesh="link5_coll"/>

                                                            <body name="fr3_link6" quat="1 1 0 0" >
                                                                <inertial pos="0.0597131 -0.0410295 -0.0101693" quat="0.621301 0.552665 0.510011 0.220081"
                                                                mass="1.81704" diaginertia="0.0175039 0.0161123 0.00193529"/>
                                                                <joint name="fr3_joint6" axis="0 0 1" range="0.5445 4.5169" actuatorfrcrange="-12 12"/>
                                                                <geom mesh="link6_0" material="button_green" class="visual"/>
                                                                <geom mesh="link6_1" material="white" class="visual"/>
                                                                <geom mesh="link6_2" material="white" class="visual"/>
                                                                <geom mesh="link6_3" material="gray" class="visual"/>
                                                                <geom mesh="link6_4" material="button_red" class="visual"/>
                                                                <geom mesh="link6_5" material="white" class="visual"/>
                                                                <geom mesh="link6_6" material="black" class="visual"/>
                                                                <geom mesh="link6_7" material="button_blue" class="visual"/>
                                                                <geom name="fr3_link6_collision" class="collision" mesh="link6_coll"/>

                                                                <body name="fr3_link7" pos="0.088 0 0" quat="1 1 0 0" >
                                                                    <inertial pos="0.00452258 0.00862619 -0.0161633" quat="0.727579 0.0978688 -0.24906 0.63168"
                                                                        mass="0.627143" diaginertia="0.000223836 0.000223642 5.64132e-07"/>
                                                                    <joint name="fr3_joint7" axis="0 0 1" range="-3.0159 3.0159" actuatorfrcrange="-12 12"/>
                                                                    <geom mesh="link7_0" material="black" class="visual"/>
                                                                    <geom mesh="link7_1" material="white" class="visual"/>
                                                                    <geom mesh="link7_2" material="white" class="visual"/>
                                                                    <geom mesh="link7_3" material="black" class="visual"/>
                                                                    <geom name="fr3_link7_collision" class="collision" mesh="link7_coll"/>
                                                                    <site name="attachment_site" pos="0 0 0.107"/>
                                                                </body>
                                                            </body>
                                                        </body>
                                                    </body>
                                                </body>
                                            </body>
                                        </body>
                                    </body>
                                </body>
                            </body>
                        </body>
                    </body>
                </body>
            </body>
        </body>
        <!-- Husky -->
        
    </worldbody>

    <actuator>
        <velocity name="left_wheel"  joint="front_left_wheel"  kv="140" forcerange="-87 87" ctrlrange="-2.8973 2.8973"/>
        <velocity name="right_wheel" joint="front_right_wheel" kv="140" forcerange="-87 87" ctrlrange="-2.8973 2.8973"/> 
        <!-- <velocity name="rear_left_wheel"   joint="rear_left_wheel"   kv="140" forcerange="-87 87" ctrlrange="-2.8973 2.8973"/>  -->
        <!-- <velocity name="rear_right_wheel"  joint="rear_right_wheel"  kv="140" forcerange="-87 87" ctrlrange="-2.8973 2.8973"/>  -->

        <!-- <motor name="front_left_wheel"  joint="front_left_wheel"  ctrlrange="-50 50"/>
        <motor name="front_right_wheel" joint="front_right_wheel" ctrlrange="-50 50"/> 
        <motor name="rear_left_wheel"   joint="rear_left_wheel"   ctrlrange="-50 50"/> 
        <motor name="rear_right_wheel"  joint="rear_right_wheel"  ctrlrange="-50 50"/>  -->

        <motor name="fr3_joint1" joint="fr3_joint1" ctrlrange="-87 87"/>
        <motor name="fr3_joint2" joint="fr3_joint2" ctrlrange="-87 87"/>
        <motor name="fr3_joint3" joint="fr3_joint3" ctrlrange="-87 87"/>
        <motor name="fr3_joint4" joint="fr3_joint4" ctrlrange="-87 87"/>
        <motor name="fr3_joint5" joint="fr3_joint5" ctrlrange="-12 12"/>
        <motor name="fr3_joint6" joint="fr3_joint6" ctrlrange="-12 12"/>
        <motor name="fr3_joint7" joint="fr3_joint7" ctrlrange="-12 12"/>
    </actuator>

    <sensor> 
        <framepos name="position_sensor" objtype="site" objname="husky_site"/> 
        <framequat name="orientation_sensor" objtype="site" objname="husky_site"/> 
        <framelinvel name="linear_velocity_sensor" objtype="site" objname="husky_site"/> 
        <frameangvel name="angular_velocity_sensor" objtype="site" objname="husky_site"/> 
    </sensor>

    <equality>
        <joint name="left_wheels_gear"
            joint1="front_left_wheel"
            joint2="rear_left_wheel"
            polycoef="0 1 0 0 0"/>

        <joint name="right_wheels_gear"
            joint1="front_right_wheel"
            joint2="rear_right_wheel"
            polycoef="0 1 0 0 0"/>
    </equality>

</mujoco>